---
title: 第七章 迭代器和生成器
date: 2020-11-27
categories:
 - 笔记
tags:
 - javascript高级程序设计
 - js
---

## yield

### 作为参数

除了可以作为函数的中间返回语句使用，`yield`关键字还可以作为函数的中间参数使用。上一次让生成器函数暂停的`yield`关键字会接收到传给`next()`方法的第一个值。这里有个地方不太好理解————第一次调用`next()`传入的值不会被使用，因为这一次调用是为了开始执行生成器函数：

```javascript
function * generatorFn(initial){
    console.log(initial)
    console.log(yield)
    console.log(yield)
}
let generatorObject=generatorFn('foo')

generatorObject.next('bar')//foo
generatorObject.next('baz')//baz
generatorObject.next('qux')//qux

```

### 同时用于输入输出

`yield`关键字可以同时用于输入和输出，如下例所示：

```javascript
function * generatorFn(){
    return yield 'foo'
}
let generatorObject=generatorFn()

console.log(generatorObject.next()) //{done:false,value:'foo'}
console.log(generatorObject.next('bar')) //{done:true,value:'bar'}
```

因为函数必须对整个表达式求值才能确定要返回的值，所以它在遇到`yield`关键字时暂停执行并计算出要产生的值：`foo`。下一次调用`next()`传入了`bar`，作为交给同一个`yield`的值。然后这个值被确定为本次生成器要返回的值。

### 迭代可迭代对象

可以使用星号增强`yield`的行为，让它能够迭代一个可迭代对象，从而一次产出一个值：

```javascript
function * generatorFn(){
    for(const x of [1,2,3]){
        yield x;
    }
}
// 下面与上面等价
function * generatorFn(){
    yield * [1,2,3]
}

// 输出
let generatorObject=generatorFn()

for(const x of generatorObject){
    console.log(x)
}
// 1
// 2
// 3
```

## 终止生成器

### return()

`return()`和`throw()`方法会强制生成器进入关闭状态。提供给`return()`的值，就是终止的值：

```javascript
function * generatorFn(){
    yield * [1,2,3]
}

let g=generatorFn()

console.log(g)  // generatorFn(<suspended>)
console.log(g.return(4))  // {done:true,value:4}
console.log(g)  // generatorFn(<closed>)
```

只要进入关闭状态，就无法恢复了。后续调用`next()`会显示`done:true`，且提供的任何值都不会被存储和传播。

### throw()

`throw()`会在暂停的时候将一个错误注入到生成器中，如果错误未被处理，生成器就会关闭：

```javascript
function * generatorFn(){
    yield * [1,2,3]
}

let g=generatorFn()

console.log(g)  // generatorFn(<suspended>)
try{
    g.throw('foo')
}catch(e){
    console.log(e) // foo
}
console.log(g)  // generatorFn(<closed>)
```

但是如果生成器内部处理了这个错误，那么生成器就不会关闭，而且还可以恢复执行。错误处理会跳过对应的`yield`，因此在这个例子中会跳过一个值。比如：

```javascript
function * generatorFn(){
    for(const x of [1,2,3]){
        try{
            yield x;
        }catch(e){}
    }
}

let g=generatorFn()

console.log(g.next())  // {done:false,value:1}
g.throw('foo')  
console.log(g.next())  // {done:false,value:3}
```

这个例子中，错误在生成器内部被捕获，所以不会产生相对应的2。然而继续执行时，再次遇到yield时会产出3

> 如果生成器对象还没有开始执行，那么调用`throw()`抛出的错误不会再函数内部被捕获，因为这相当于在函数外部抛出了错误。

> 自备：即上面第一行就调用`g.throw()`